Workbook

Sheet PROTOCOLO
A1: PROTOCOLO EXPERIMENTAL DA DISSERTAÇÃO
A2: Avaliação Experimental de Ferramentas de IA Generativa na Análise de Documentos Financeiros da Administração Pública
A4: 1. IDENTIFICAÇÃO DA PESQUISA
A5: Título da pesquisa | B5: Avaliação Experimental de Ferramentas de IA Generativa na Análise de Documentos Financeiros da Administração Pública
A6: Objetivo geral | B6: Avaliar como diferentes ferramentas de Inteligência Artificial Generativa analisam documentos administrativos públicos.
A7: Objetivo da aplicação experimental | B7: Comparar, sob as mesmas condições possíveis (mesmo documento, mesma pergunta, mesmo contexto de teste), as respostas produzidas por 6 configurações de ferramentas de IA generativa frente a um conjunto padronizado de documentos administrativos e perguntas, contrastando cada resposta com uma resposta de referência (Gold) elaborada pelo pesquisador.
A9: 2. UNIDADE EXPERIMENTAL
A10: Unidade experimental | B10: Documento administrativo + Pergunta/prompt padronizado + Configuração de IA testada.
A11: Entrada (input) | B11: Documento administrativo público + pergunta/prompt padronizado, aplicados à ferramenta de IA.
A12: Saída (output) | B12: Resposta produzida pela ferramenta de Inteligência Artificial para o par documento+pergunta.
A13: Conceito de Gold | B13: Resposta de referência elaborada previamente pelo pesquisador, considerada correta e fundamentada diretamente no documento analisado, com evidência documental explícita (página/seção/trecho).
A14: Comparação realizada | B14: Documento + Pergunta + Gold x Documento + Pergunta + Resposta da IA, para cada uma das 9 configurações.
A16: 3. ESCOPO DO EXPERIMENTO
A17: Documentos analisados | B17: 06 documentos administrativos públicos, organizados em grupo de financeiro
A18: Ferramentas testadas | B18: ChatGPT, Claude e Gemini, cada uma em modalidade Gratuita, Paga 1 e Paga 2.
A19: Número de configurações de IA | B19: 6 (nove) configurações, avaliadas individualmente e sem agrupamento automático.
A20: Banco de perguntas | B20: 33 perguntas gerais (P01-P33)
A22: 4. CRITÉRIOS E CATEGORIAS
A23: Critérios de avaliação | B23: Correção, Completude, Precisão, Consistência, Clareza, Profundidade, Fidelidade Documental, Alucinação, Omissão, Interpretação e Conformidade (ver aba DICIONÁRIO DE DADOS).
A24: Categorias de perguntas | B24: Identificação, Localização, Extração, Organização, Interpretação, Identificação de Inconsistências, Detecção de Erros, Identificação de Omissões, Conformidade Documental, Análise de Risco, Comparação, Síntese, Rastreabilidade da Informação, Análise de Relações entre Informações
A25: Níveis de dificuldade | B25: Nível 1 - Extração Direta; Nível 2 - Localização e Organização; Nível 3 - Interpretação; Nível 4 - Análise; Nível 5 - Raciocínio Documental
A27: 5. REGRAS DE APLICAÇÃO E COMPARAÇÃO
A28: Regras de aplicação | B28: Cada configuração de IA recebe, sempre que possível, o mesmo documento, a mesma pergunta/prompt e o mesmo contexto de teste (nova conversa, sem histórico prévio, salvo quando o parâmetro de continuidade for objeto específico do teste).
A29: Regras de comparação | B29: As 6 configurações são comparadas separadamente entre si (não agrupadas). São admitidas comparações descritivas: por ferramenta . Não é criado ranking, nota prévia ou classificação de melhor/pior ferramenta: os resultados decorrem exclusivamente dos dados obtidos empiricamente.
A30: Controle das condições experimentais | B30: Registrado na aba CONTROLE METODOLÓGICO: mesmo documento, mesma versão, mesma pergunta, mesmo prompt, mesmo idioma, mesmo contexto, mesmo formato de arquivo, tentativas, intervenções humanas, acesso à internet, uso de memória/contexto e validade/comparabilidade de cada teste.
A32: 6. DECLARAÇÃO METODOLÓGICA
A33: Princípio de neutralidade | B33: Esta planilha não estabelece previamente qual ferramenta, modalidade, plano ou modelo é superior. Os resultados devem ser obtidos empiricamente a partir dos testes, e os cálculos de resultado apenas consolidam os dados inseridos pelo pesquisador.
A34: Regra de aplicação padronizada | B34: "Todas as ferramentas deverão receber, sempre que possível, o mesmo documento, a mesma pergunta e o mesmo contexto de teste."

Sheet DOCUMENTOS
A1: ABA 2 - DOCUMENTOS DO EXPERIMENTO (20 documentos / 5 grupos)
A2: ID_Doc | B2: Grupo | C2: Categoria | D2: Tipo Documental | E2: Nome do Documento | F2: Nº/Identificação | G2: Nº SEI | H2: Nº Processo | I2: Data | J2: Setor Responsável | K2: Finalidade | L2: Descrição | M2: Qtd. Páginas | N2: Formato do Arquivo | O2: Tamanho do Arquivo | P2: Observações | Q2: Link/Referência SEI | R2: Situação do Documento | S2: Documento Relacionado | T2: Processo Relacionado
A3: 1 | B3: Grupo 4 - Informação Financeira | C3: Financeiro | D3: Planilha de Custos | E3: Planilha Mapa Comparativo de Preços | F3: Mapa Comparativo de Preços | G3: 0631096 | H3: 23854.007448/2024-94 | Q3: SEI nº 0631096 (processo 23854.007448/2024-94)
A4: 2 | B4: Grupo 4 - Informação Financeira | C4: Financeiro | D4: Pesquisa de Preços | E4: Relatório Pesquisa de Preço - Banco de Preços | F4: Pesquisa de Preço - Banco de Preços | G4: 0631080 | H4: 23854.007448/2024-94 | Q4: SEI nº 0631080 (processo 23854.007448/2024-94)
A5: 3 | B5: Grupo 4 - Informação Financeira | C5: Financeiro | D5: Medição | E5: Boletim de Medição | F5: Boletim de Medição | G5: 0572838 | H5: 23854.003175/2026-71 | Q5: SEI nº 0572838 (processo 23854.003175/2026-71)
A6: 4 | B6: Grupo 4 - Informação Financeira | C6: Financeiro | D6: Nota Fiscal | E6: Nota Fiscal nº 119.235 - Março/26 | F6: NF 119.235 | G6: 0574135 | H6: 23854.003175/2026-71 | Q6: SEI nº 0574135 (processo 23854.003175/2026-71)
A7: 5 | B7: Grupo 4 - Informação Financeira | C7: Financeiro | D7: Nota de Empenho | E7: Empenho 2026NE000070 - Reforço | F7: NE 2026NE000070 | G7: 0601218 | H7: 23854.008489/2024-06 | Q7: SEI nº 0601218 (processo 23854.008489/2024-06)
A8: 6 | B8: Grupo 4 - Informação Financeira | C8: Financeiro | D8: Ordem Bancária | E8: Ordem Bancária 2026OB000456 | F8: OB 2026OB000456 | G8: 0604691 | H8: 23854.003091/2026-37 | Q8: SEI nº 0604691 (processo 23854.003091/2026-37)

Sheet BANCO DE PERGUNTAS
A1: ABA 3 - BANCO DE PERGUNTAS (33 gerais + 20 específicas por tipo documental)
A2: ID_Pergunta | B2: Categoria | C2: Subcategoria | D2: Pergunta | E2: Prompt Completo | F2: Objetivo | G2: Tipo Documental Aplicável | H2: Nível de Dificuldade | I2: Habilidade Avaliada | J2: Informação Esperada | K2: Permite 'Não Consta no Documento'? | L2: Requer Comparação com Outro Documento? | M2: Observação Metodológica
A3: P01 | B3: Identificação | C3: Objeto do documento | D3: Qual é o objeto principal deste documento? | E3: Com base exclusivamente no documento fornecido, responda: Qual é o objeto principal deste documento? Caso a informação não conste no documento, declare explicitamente 'não consta no documento'. | F3: Avaliar a capacidade da ferramenta de identificar informações do tipo 'identificação'. | G3: Geral (todos os tipos) | H3: 1 | I3: Identificar | J3: Ver evidência documental correspondente na aba GOLD. | K3: Não | L3: Não | M3: Pergunta geral, aplicável a qualquer tipo documental do corpus, resguardadas as adaptações de vocabulário indicadas entre colchetes.
A4: P02 | B4: Identificação | C4: Numeração do documento | D4: Qual é o número ou identificação do documento? | E4: Com base exclusivamente no documento fornecido, responda: Qual é o número ou identificação do documento? Caso a informação não conste no documento, declare explicitamente 'não consta no documento'. | F4: Avaliar a capacidade da ferramenta de identificar informações do tipo 'identificação'. | G4: Geral (todos os tipos) | H4: 1 | I4: Identificar | J4: Ver evidência documental correspondente na aba GOLD. | K4: Não | L4: Não | M4: Pergunta geral, aplicável a qualquer tipo documental do corpus, resguardadas as adaptações de vocabulário indicadas entre colchetes.
A5: P03 | B5: Identificação | C5: Processo relacionado | D5: Qual é o número do processo relacionado? | E5: Com base exclusivamente no documento fornecido, responda: Qual é o número do processo relacionado? Caso a informação não conste no documento, declare explicitamente 'não consta no documento'. | F5: Avaliar a capacidade da ferramenta de identificar informações do tipo 'identificação'. | G5: Geral (todos os tipos) | H5: 1 | I5: Identificar | J5: Ver evidência documental correspondente na aba GOLD. | K5: Sim | L5: Não | M5: Pergunta geral, aplicável a qualquer tipo documental do corpus, resguardadas as adaptações de vocabulário indicadas entre colchetes.
A6: P04 | B6: Identificação | C6: Data do documento | D6: Qual é a data do documento? | E6: Com base exclusivamente no documento fornecido, responda: Qual é a data do documento? Caso a informação não conste no documento, declare explicitamente 'não consta no documento'. | F6: Avaliar a capacidade da ferramenta de identificar informações do tipo 'identificação'. | G6: Geral (todos os tipos) | H6: 1 | I6: Identificar | J6: Ver evidência documental correspondente na aba GOLD. | K6: Sim | L6: Não | M6: Pergunta geral, aplicável a qualquer tipo documental do corpus, resguardadas as adaptações de vocabulário indicadas entre colchetes.
A7: P05 | B7: Identificação | C7: Setor responsável | D7: Qual setor ou unidade está relacionado ao documento? | E7: Com base exclusivamente no documento fornecido, responda: Qual setor ou unidade está relacionado ao documento? Caso a informação não conste no documento, declare explicitamente 'não consta no documento'. | F7: Avaliar a capacidade da ferramenta de identificar informações do tipo 'identificação'. | G7: Geral (todos os tipos) | H7: 1 | I7: Identificar | J7: Ver evidência documental correspondente na aba GOLD. | K7: Sim | L7: Não | M7: Pergunta geral, aplicável a qualquer tipo documental do corpus, resguardadas as adaptações de vocabulário indicadas entre colchetes.
A8: P06 | B8: Identificação | C8: Partes envolvidas | D8: Quais são as partes ou instituições mencionadas? | E8: Com base exclusivamente no documento fornecido, responda: Quais são as partes ou instituições mencionadas? Caso a informação não conste no documento, declare explicitamente 'não consta no documento'. | F8: Avaliar a capacidade da ferramenta de identificar/organizar informações do tipo 'identificação'. | G8: Geral (todos os tipos) | H8: 2 | I8: Identificar/Organizar | J8: Ver evidência documental correspondente na aba GOLD. | K8: Sim | L8: Não | M8: Pergunta geral, aplicável a qualquer tipo documental do corpus, resguardadas as adaptações de vocabulário indicadas entre colchetes.
A9: P07 | B9: Localização | C9: Informação em seção específica | D9: Qual informação específica está apresentada na seção 08? | E9: Com base exclusivamente no documento fornecido, responda: Qual informação específica está apresentada na seção 8? Caso a informação não conste no documento, declare explicitamente 'não consta no documento'. | F9: Avaliar a capacidade da ferramenta de localizar informações do tipo 'localização'. | G9: Geral (todos os tipos) | H9: 2 | I9: Localizar | J9: Ver evidência documental correspondente na aba GOLD. | K9: Sim | L9: Não | M9: Pergunta geral, aplicável a qualquer tipo documental do corpus, resguardadas as adaptações de vocabulário indicadas entre colchetes.
A10: P08 | B10: Localização | C10: Localização de informação | D10: Em qual seção do documento está localizada a informação solicitada? | E10: Com base exclusivamente no documento fornecido, responda: Em qual seção do documento está localizada a informação solicitada? Caso a informação não conste no documento, declare explicitamente 'não consta no documento'. | F10: Avaliar a capacidade da ferramenta de localizar informações do tipo 'localização'. | G10: Geral (todos os tipos) | H10: 2 | I10: Localizar | J10: Ver evidência documental correspondente na aba GOLD. | K10: Sim | L10: Não | M10: Pergunta geral, aplicável a qualquer tipo documental do corpus, resguardadas as adaptações de vocabulário indicadas entre colchetes.
A11: P09 | B11: Localização | C11: Valor de item | D11: Qual é o valor indicado para o Valor Total Anual do Objeto licitado? | E11: Com base exclusivamente no documento fornecido, responda: Qual é o valor indicado para [item]? Caso a informação não conste no documento, declare explicitamente 'não consta no documento'. | F11: Avaliar a capacidade da ferramenta de localizar/extrair informações do tipo 'localização'. | G11: Geral (todos os tipos) | H11: 1 | I11: Localizar/Extrair | J11: Ver evidência documental correspondente na aba GOLD. | K11: Sim | L11: Não | M11: Pergunta geral, aplicável a qualquer tipo documental do corpus, resguardadas as adaptações de vocabulário indicadas entre colchetes.
A12: P10 | B12: Localização | C12: Data de evento | D12: Qual é a data indicada para de assinatura de todos os membros da comissão da contratação? | E12: Com base exclusivamente no documento fornecido, responda: Qual é a data indicada para [evento]? Caso a informação não conste no documento, declare explicitamente 'não consta no documento'. | F12: Avaliar a capacidade da ferramenta de localizar/extrair informações do tipo 'localização'. | G12: Geral (todos os tipos) | H12: 1 | I12: Localizar/Extrair | J12: Ver evidência documental correspondente na aba GOLD. | K12: Sim | L12: Não | M12: Pergunta geral, aplicável a qualquer tipo documental do corpus, resguardadas as adaptações de vocabulário indicadas entre colchetes.
A13: P11 | B13: Extração | C13: Dados estruturados | D13: Extraia os principais dados do documento em formato estruturado. | E13: Com base exclusivamente no documento fornecido, responda: Extraia os principais dados do documento em formato estruturado. Caso a informação não conste no documento, declare explicitamente 'não consta no documento'. | F13: Avaliar a capacidade da ferramenta de extrair/organizar informações do tipo 'extração'. | G13: Geral (todos os tipos) | H13: 2 | I13: Extrair/Organizar | J13: Ver evidência documental correspondente na aba GOLD. | K13: Não | L13: Não | M13: Pergunta geral, aplicável a qualquer tipo documental do corpus, resguardadas as adaptações de vocabulário indicadas entre colchetes.
A14: P12 | B14: Extração | C14: Valores financeiros | D14: Liste os valores financeiros presentes no documento. | E14: Com base exclusivamente no documento fornecido, responda: Liste os valores financeiros presentes no documento. Caso a informação não conste no documento, declare explicitamente 'não consta no documento'. | F14: Avaliar a capacidade da ferramenta de extrair informações do tipo 'extração'. | G14: Geral (todos os tipos) | H14: 2 | I14: Extrair | J14: Ver evidência documental correspondente na aba GOLD. | K14: Sim | L14: Não | M14: Pergunta geral, aplicável a qualquer tipo documental do corpus, resguardadas as adaptações de vocabulário indicadas entre colchetes.
... A35: P33 | B35: Síntese | C35: Informações mais relevantes | D35: Quais são as três informações mais importantes para um servidor responsável pela análise? | E35: Com base exclusivamente no documento fornecido, responda: Quais são as três informações mais importantes para um servidor responsável pela análise? Caso a informação não conste no documento, declare explicitamente 'não consta no documento'. | F35: Avaliar a capacidade da ferramenta de sintetizar/avaliar relevância informações do tipo 'síntese'. | G35: Geral (todos os tipos) | H35: 3 | I35: Sintetizar/Avaliar Relevância | J35: Ver evidência documental correspondente na aba GOLD. | K35: Não | L35: Não | M35: Pergunta geral, aplicável a qualquer tipo documental do corpus, resguardadas as adaptações de vocabulário indicadas entre colchetes.

Sheet AVALIAÇÃO
A1: ABA 5 - AVALIAÇÃO (uma linha por Documento+Pergunta; um bloco de critérios por configuração de IA)
A2: ID_Doc | B2: ID_Pergunta | C2: Documento | D2: Pergunta | E2: Categoria | F2: Nível | G2: ChatGPT - teste | U2: ChatGPT - GPT-6 Astra | AI2: ChatGPT - GPT-5.6 Luna | AW2: Claude - teste | BK2: Claude - Sonnet 5 | BY2: Claude - Opus 5 | CM2: Gemini - teste | DA2: Gemini - 3.1 Pro | DO2: Gemini - 3.5 Flash
G3: Resposta | H3: Tempo (s) | I3: Correção | J3: Completude | K3: Precisão | L3: Consistência | M3: Clareza | N3: Profundidade | O3: Fidelidade Documental | P3: Alucinação | Q3: Omissão | R3: Erro | S3: Tipo de Erro | T3: Justificativa | U3: Resposta | V3: Tempo (s) | W3: Correção | X3: Completude | Y3: Precisão | Z3: Consistência | AA3: Clareza | AB3: Profundidade | AC3: Fidelidade Documental | AD3: Alucinação | AE3: Omissão | AF3: Erro | AG3: Tipo de Erro | AH3: Justificativa | AI3: Resposta | AJ3: Tempo (s) | AK3: Correção | AL3: Completude | AM3: Precisão | AN3: Consistência | AO3: Clareza | AP3: Profundidade | AQ3: Fidelidade Documental | AR3: Alucinação | AS3: Omissão | AT3: Erro | AU3: Tipo de Erro | AV3: Justificativa | AW3: Resposta | AX3: Tempo (s) | AY3: Correção | AZ3: Completude | BA3: Precisão | BB3: Consistência | BC3: Clareza | BD3: Profundidade | BE3: Fidelidade Documental | BF3: Alucinação | BG3: Omissão | BH3: Erro | BI3: Tipo de Erro | BJ3: Justificativa | BK3: Resposta | BL3: Tempo (s) | BM3: Correção | BN3: Completude | BO3: Precisão | BP3: Consistência | BQ3: Clareza | BR3: Profundidade | BS3: Fidelidade Documental | BT3: Alucinação | BU3: Omissão | BV3: Erro | BW3: Tipo de Erro | BX3: Justificativa | BY3: Resposta | BZ3: Tempo (s) | CA3: Correção | CB3: Completude | CC3: Precisão | CD3: Consistência | CE3: Clareza | CF3: Profundidade | CG3: Fidelidade Documental | CH3: Alucinação | CI3: Omissão | CJ3: Erro | CK3: Tipo de Erro | CL3: Justificativa | CM3: Resposta | CN3: Tempo (s) | CO3: Correção | CP3: Completude | CQ3: Precisão | CR3: Consistência | CS3: Clareza | CT3: Profundidade | CU3: Fidelidade Documental | CV3: Alucinação | CW3: Omissão | CX3: Erro | CY3: Tipo de Erro | CZ3: Justificativa | DA3: Resposta | DB3: Tempo (s) | DC3: Correção | DD3: Completude | DE3: Precisão | DF3: Consistência | DG3: Clareza | DH3: Profundidade | DI3: Fidelidade Documental | DJ3: Alucinação | DK3: Omissão | DL3: Erro | DM3: Tipo de Erro | DN3: Justificativa | DO3: Resposta | DP3: Tempo (s) | DQ3: Correção | DR3: Completude | DS3: Precisão | DT3: Consistência | DU3: Clareza | DV3: Profundidade | DW3: Fidelidade Documental | DX3: Alucinação | DY3: Omissão | DZ3: Erro | EA3: Tipo de Erro | EB3: Justificativa
A4: 11 | B4: P01 | C4: {=IFERROR(INDEX(DOCUMENTOS!$E:$E,MATCH($A4,DOCUMENTOS!$A:$A,0)),"")} | D4: {=IFERROR(INDEX('BANCO DE PERGUNTAS'!$D:$D,MATCH($B4,'BANCO DE PERGUNTAS'!$A:$A,0)),"")} -> Qual é o objeto principal deste documento? | E4: {=IFERROR(INDEX('BANCO DE PERGUNTAS'!$B:$B,MATCH($B4,'BANCO DE PERGUNTAS'!$A:$A,0)),"")} -> Identificação | F4: {=IFERROR(INDEX('BANCO DE PERGUNTAS'!$H:$H,MATCH($B4,'BANCO DE PERGUNTAS'!$A:$A,0)),"")} -> 1 | U4: Comparar preços para serviços de limpeza e conservação diurna, 44 horas, com materiais sob demanda e equipamentos, na Universidade Federal de Jataí, utilizando o contrato vigente atualizado e pesquisa no Banco de Preços. | W4: 2 | X4: 2 | Y4: 2 | Z4: 2 | AA4: 2 | AB4: 2 | AC4: 2 | AD4: Não | AE4: Não | AF4: Não | AI4: A planilha apresenta o mapa comparativo de preços para a contratação de serviços de limpeza e conservação, incluindo mão de obra, materiais sob demanda e equipamentos. | AK4: 2 | AL4: 2 | AM4: 2 | AN4: 2 | AO4: 2 | AP4: 2 | AQ4: 2 | AR4: Não | AS4: Não | AT4: Não | BK4: Mapa comparativo de preços para subsidiar a análise do valor do contrato de prestação de serviço de limpeza e conservação (diurna, 44h) da Universidade Federal de Jataí, incluindo material sob demanda e equipamentos com BDI. | BM4: 2 | BN4: 2 | BO4: 2 | BP4: 2 | BQ4: 2 | BR4: 2 | BS4: 2 | BT4: Não | BU4: Não | BV4: Não | BY4: Mapa comparativo de preços destinado a estimar o valor da contratação de prestação de serviço de limpeza e conservação (diurna, 44 horas, categoria A) para a Universidade Federal de Jataí, incluindo material sob demanda + BDI e equipamentos + BDI. | CA4: 2 | CB4: 2 | CC4: 2 | CD4: 2 | CE4: 2 | CF4: 2 | CG4: 2 | CH4: Não | CI4: Não | CJ4: Não | DA4: Mapa Comparativo de Preços para contratação de prestação de serviço de limpeza e conservação, fornecimento de material e equipamentos. | DC4: 2 | DD4: 2 | DE4: 2 | DF4: 2 | DG4: 2 | DH4: 2 | DI4: 2 | DJ4: Não | DK4: Não | DL4: Não | DO4: Mapa comparativo de preços para prestação de serviço de limpeza e conservação diurna (44 horas), material sob demanda e equipamentos. | DQ4: 2 | DR4: 2 | DS4: 2 | DT4: 2 | DU4: 2 | DV4: 2 | DW4: 2 | DX4: Não | DY4: Não | DZ4: Não
A5: 11 | B5: P02 | C5: {=IFERROR(INDEX(DOCUMENTOS!$E:$E,MATCH($A5,DOCUMENTOS!$A:$A,0)),"")} | D5: {=IFERROR(INDEX('BANCO DE PERGUNTAS'!$D:$D,MATCH($B5,'BANCO DE PERGUNTAS'!$A:$A,0)),"")} -> Qual é o número ou identificação do documento? | E5: {=IFERROR(INDEX('BANCO DE PERGUNTAS'!$B:$B,MATCH($B5,'BANCO DE PERGUNTAS'!$A:$A,0)),"")} -> Identificação | F5: {=IFERROR(INDEX('BANCO DE PERGUNTAS'!$H:$H,MATCH($B5,'BANCO DE PERGUNTAS'!$A:$A,0)),"")} -> 1 | U5: Identificação no conteúdo: “Planilha - Mapa Comparativo de Preços”. Número próprio do documento: não consta no documento. O identificador 0631096 aparece no nome do arquivo fornecido. | W5: 2 | X5: 2 | Y5: 2 | Z5: 2 | AA5: 2 | AB5: 2 | AC5: 2 | AD5: Não | AE5: Não | AF5: Não | AI5: Não consta no corpo da planilha um número individual do documento. O título é “Mapa Comparativo de Preços”. | AK5: 2 | AL5: 2 | AM5: 2 | AN5: 2 | AO5: 2 | AP5: 2 | AQ5: 2 | AR5: Não | AS5: Não | AT5: Não | BK5: O documento não apresenta um número próprio de identificação (é uma "Planilha - Mapa Comparativo de Preços"). Refere-se ao Contrato nº 113/2024 e ao Termo de Apostilamento nº 01/2026 (0616763). | BM5: 2 | BN5: 2 | BO5: 2 | BP5: 2 | BQ5: 2 | BR5: 2 | BS5: 2 | BT5: Não | BU5: Não | BV5: Não | BY5: O documento se identifica apenas como 'PLANILHA - MAPA COMPARATIVO DE PREÇOS'; o corpo não traz número SEI próprio. O nome do arquivo indica o documento SEI nº 0631096. | CA5: 2 | CB5: 2 | CC5: 2 | CD5: 2 | CE5: 2 | CF5: 2 | CG5: 2 | CH5: Não | CI5: Não | CJ5: Não | DA5: Planilha Mapa Comparativo de Preços (0631096). | DC5: 2 | DD5: 2 | DE5: 2 | DF5: 2 | DG5: 2 | DH5: 2 | DI5: 2 | DJ5: Não | DK5: Não | DL5: Não | DO5: Documento 0631096 (Mapa Comparativo de Preços). | DQ5: 1 | DR5: 2 | DS5: 1 | DT5: 1 | DU5: 2 | DV5: 2 | DW5: 1 | DX5: Não | DY5: Não | DZ5: Sim | EA5: Erro de interpretação
A6: 11 | B6: P03 | C6: {=IFERROR(INDEX(DOCUMENTOS!$E:$E,MATCH($A6,DOCUMENTOS!$A:$A,0)),"")} | D6: {=IFERROR(INDEX('BANCO DE PERGUNTAS'!$D:$D,MATCH($B6,'BANCO DE PERGUNTAS'!$A:$A,0)),"")} -> Qual é o número do processo relacionado? | E6: {=IFERROR(INDEX('BANCO DE PERGUNTAS'!$B:$B,MATCH($B6,'BANCO DE PERGUNTAS'!$A:$A,0)),"")} -> Identificação | F6: {=IFERROR(INDEX('BANCO DE PERGUNTAS'!$H:$H,MATCH($B6,'BANCO DE PERGUNTAS'!$A:$A,0)),"")} -> 1 | U6: Processo administrativo SEI 23854.007448/2024-94. | W6: 2 | X6: 2 | Y6: 2 | Z6: 2 | AA6: 2 | AB6: 2 | AC6: 2 | AD6: Não | AE6: Não | AF6: Não | AI6: 23854.007448/2024-94. | AK6: 2 | AL6: 2 | AM6: 2 | AN6: 2 | AO6: 2 | AP6: 2 | AQ6: 2 | AR6: Não | AS6: Não | AT6: Não | BK6: Processo Administrativo SEI nº 23854.007448/2024-94. | BM6: 2 | BN6: 2 | BO6: 2 | BP6: 2 | BQ6: 2 | BR6: 2 | BS6: 2 | BT6: Não | BU6: Não | BV6: Não | BY6: Processo Administrativo SEI nº 23854.007448/2024-94. | CA6: 2 | CB6: 2 | CC6: 2 | CD6: 2 | CE6: 2 | CF6: 2 | CG6: 2 | CH6: Não | CI6: Não | CJ6: Não | DA6: Processo Administrativo SEI 23854.007448/2024-94. | DC6: 2 | DD6: 2 | DE6: 2 | DF6: 2 | DG6: 2 | DH6: 2 | DI6: 2 | DJ6: Não | DK6: Não | DL6: Não | DO6: Processo Administrativo SEI 23854.007448/2024-94. | DQ6: 2 | DR6: 2 | DS6: 2 | DT6: 2 | DU6: 2 | DV6: 2 | DW6: 2 | DX6: Não | DY6: Não | DZ6: Não
A7: 11 | B7: P04 | C7: {=IFERROR(INDEX(DOCUMENTOS!$E:$E,MATCH($A7,DOCUMENTOS!$A:$A,0)),"")} | D7: {=IFERROR(INDEX('BANCO DE PERGUNTAS'!$D:$D,MATCH($B7,'BANCO DE PERGUNTAS'!$A:$A,0)),"")} -> Qual é a data do documento? | E7: {=IFERROR(INDEX('BANCO DE PERGUNTAS'!$B:$B,MATCH($B7,'BANCO DE PERGUNTAS'!$A:$A,0)),"")} -> Identificação | F7: {=IFERROR(INDEX('BANCO DE PERGUNTAS'!$H:$H,MATCH($B7,'BANCO DE PERGUNTAS'!$A:$A,0)),"")} -> 1 | U7: 24 de agosto de 2026, em Jataí. A representação da assinatura digital indica 24/08/2026, às 10:02:42, fuso -0300. | W7: 2 | X7: 2 | Y7: 2 | Z7: 2 | AA7: 2 | AB7: 2 | AC7: 2 | AD7: Não | AE7: Não | AF7: Não | AI7: Jataí, 24 de agosto de 2026. | AK7: 2 | AL7: 2 | AM7: 2 | AN7: 2 | AO7: 2 | AP7: 2 | AQ7: 2 | AR7: Não | AS7: Não | AT7: Não | BK7: Jataí, 24 de agosto de 2026 (data também confirmada na assinatura digital: 24/08/2026 10:02:42-0300). | BM7: 2 | BN7: 2 | BO7: 2 | BP7: 2 | BQ7: 2 | BR7: 2 | BS7: 2 | BT7: Não | BU7: Não | BV7: Não | BY7: Jataí, 24 de agosto de 2026 (assinatura digital gov.br em 24/08/2026, às 10:02:42, fuso -0300). | CA7: 2 | CB7: 2 | CC7: 2 | CD7: 2 | CE7: 2 | CF7: 2 | CG7: 2 | CH7: Não | CI7: Não | CJ7: Não | DA7: 24 de Agosto de 2026. | DC7: 2 | DD7: 2 | DE7: 2 | DF7: 2 | DG7: 2 | DH7: 2 | DI7: 2 | DJ7: Não | DK7: Não | DL7: Não | DO7: 24 de Agosto de 2026. | DQ7: 2 | DR7: 2 | DS7: 2 | DT7: 2 | DU7: 2 | DV7: 2 | DW7: 2 | DX7: Não | DY7: Não | DZ7: Não
A8: 11 | B8: P05 | C8: {=IFERROR(INDEX(DOCUMENTOS!$E:$E,MATCH($A8,DOCUMENTOS!$A:$A,0)),"")} | D8: {=IFERROR(INDEX('BANCO DE PERGUNTAS'!$D:$D,MATCH($B8,'BANCO DE PERGUNTAS'!$A:$A,0)),"")} -> Qual setor ou unidade está relacionado ao documento? | E8: {=IFERROR(INDEX('BANCO DE PERGUNTAS'!$B:$B,MATCH($B8,'BANCO DE PERGUNTAS'!$A:$A,0)),"")} -> Identificação | F8: {=IFERROR(INDEX('BANCO DE PERGUNTAS'!$H:$H,MATCH($B8,'BANCO DE PERGUNTAS'!$A:$A,0)),"")} -> 1 | U8: Pró-Reitoria de Administração e Finanças da Universidade Federal de Jataí (PROAD/UFJ). | W8: 2 | X8: 2 | Y8: 2 | Z8: 2 | AA8: 2 | AB8: 2 | AC8: 2 | AD8: Não | AE8: Não | AF8: Não | AI8: Universidade Federal de Jataí (UFJ), por meio da Pró-Reitoria de Administração e Finanças (PROAD/UFJ). | AK8: 2 | AL8: 2 | AM8: 2 | AN8: 2 | AO8: 2 | AP8: 2 | AQ8: 2 | AR8: Não | AS8: Não | AT8: Não | BK8: PROAD/UFJ – Pró-Reitoria de Administração e Finanças da Universidade Federal de Jataí (UFJ). | BM8: 2 | BN8: 2 | BO8: 2 | BP8: 2 | BQ8: 2 | BR8: 2 | BS8: 2 | BT8: Não | BU8: Não | BV8: Não | BY8: Pró-Reitoria de Administração e Finanças - PROAD/UFJ, da Universidade Federal de Jataí. | CA8: 2 | CB8: 2 | CC8: 2 | CD8: 2 | CE8: 2 | CF8: 2 | CG8: 2 | CH8: Não | CI8: Não | CJ8: Não | DA8: Pró-Reitoria de Administração e Finanças (PROAD/UFPROAD) da Universidade Federal de Jataí (UFJ). | DC8: 2 | DD8: 2 | DE8: 2 | DF8: 2 | DG8: 2 | DH8: 2 | DI8: 2 | DJ8: Não | DK8: Não | DL8: Não | DO8: Universidade Federal de Jataí (UFJ) - Pró-Reitoria de Administração e Finanças (PROAD/UFPROAD). | DQ8: 2 | DR8: 2 | DS8: 2 | DT8: 2 | DU8: 2 | DV8: 2 | DW8: 2 | DX8: Não | DY8: Não | DZ8: Não
A9: 11 | B9: P06 | C9: {=IFERROR(INDEX(DOCUMENTOS!$E:$E,MATCH($A9,DOCUMENTOS!$A:$A,0)),"")} | D9: {=IFERROR(INDEX('BANCO DE PERGUNTAS'!$D:$D,MATCH($B9,'BANCO DE PERGUNTAS'!$A:$A,0)),"")} -> Quais são as partes ou instituições mencionadas? | E9: {=IFERROR(INDEX('BANCO DE PERGUNTAS'!$B:$B,MATCH($B9,'BANCO DE PERGUNTAS'!$A:$A,0)),"")} -> Identificação | F9: {=IFERROR(INDEX('BANCO DE PERGUNTAS'!$H:$H,MATCH($B9,'BANCO DE PERGUNTAS'!$A:$A,0)),"")} -> 2 | U9: Universidade Federal de Jataí (UFJ); Pró-Reitoria de Administração e Finanças (PROAD/UFJ); Banco de Preços, fonte da pesquisa. Consta como signatário Marcos Paulo Pereira Fagundes. A empresa do contrato nº 113/2024 não é identificada. | W9: 2 | X9: 2 | Y9: 2 | Z9: 2 | AA9: 2 | AB9: 2 | AC9: 2 | AD9: Não | AE9: Não | AF9: Não | AI9: Universidade Federal de Jataí (UFJ); PROAD/UFJ; Banco de Preços; e o Contrato nº 113/2024 da Universidade Federal de Jataí, citado como referência. | AK9: 2 | AL9: 2 | AM9: 2 | AN9: 2 | AO9: 2 | AP9: 2 | AQ9: 2 | AR9: Não | AS9: Não | AT9: Não | BK9: Universidade Federal de Jataí (UFJ); PROAD/UFJ; Banco de Preços (site bancodeprecos.com.br), usado como fonte da pesquisa de mercado (Preço 02). | BM9: 2 | BN9: 2 | BO9: 2 | BP9: 2 | BQ9: 2 | BR9: 2 | BS9: 2 | BT9: Não | BU9: Não | BV9: Não | BY9: Universidade Federal de Jataí (UFJ) e PROAD/UFJ; o site Banco de Preços (www.bancodeprecos.com.br) como fonte de pesquisa; referência ao Contrato nº 113/2024, ao Termo de Apostilamento nº 01/2026 (0616763) e à Convenção Coletiva de Trabalho 2026/2027 (0602942); signatário Marcos Paulo Pereira Fagundes. A empresa contratada não é nominada. | CA9: 2 | CB9: 2 | CC9: 2 | CD9: 2 | CE9: 2 | CF9: 2 | CG9: 2 | CH9: Não | CI9: Não | CJ9: Não | DA9: Universidade Federal de Jataí (UFJ) e Banco de Preços. | DC9: 1 | DD9: 2 | DE9: 1 | DF9: 1 | DG9: 2 | DH9: 2 | DI9: 1 | DJ9: Não | DK9: Não | DL9: Sim | DM9: Erro de interpretação | DO9: Universidade Federal de Jataí (UFJ) e Banco de Preços. | DQ9: 1 | DR9: 2 | DS9: 1 | DT9: 1 | DU9: 2 | DV9: 2 | DW9: 1 | DX9: Não | DY9: Não | DZ9: Sim | EA9: Erro de interpretação
A10: 11 | B10: P07 | C10: {=IFERROR(INDEX(DOCUMENTOS!$E:$E,MATCH($A10,DOCUMENTOS!$A:$A,0)),"")} | D10: {=IFERROR(INDEX('BANCO DE PERGUNTAS'!$D:$D,MATCH($B10,'BANCO DE PERGUNTAS'!$A:$A,0)),"")} -> Qual informação específica está apresentada na seção 08? | E10: {=IFERROR(INDEX('BANCO DE PERGUNTAS'!$B:$B,MATCH($B10,'BANCO DE PERGUNTAS'!$A:$A,0)),"")} -> Localização | F10: {=IFERROR(INDEX('BANCO DE PERGUNTAS'!$H:$H,MATCH($B10,'BANCO DE PERGUNTAS'!$A:$A,0)),"")} -> 2 | U10: não consta no documento. O mapa tem uma página e não apresenta seção 08. | W10: 2 | X10: 2 | Y10: 2 | Z10: 2 | AA10: 2 | AB10: 2 | AC10: 2 | AD10: Não | AE10: Não | AF10: Não | AI10: Não consta no documento. A planilha não contém uma seção numerada 08. | AK10: 2 | AL10: 2 | AM10: 2 | AN10: 2 | AO10: 2 | AP10: 2 | AQ10: 2 | AR10: Não | AS10: Não | AT10: Não | BK10: Não consta "Seção 08" no documento — ele não é estruturado em seções numeradas, apenas em uma tabela única (Grupo/Item) e notas de rodapé (Preço 01 e Preço 02). | BM10: 2 | BN10: 2 | BO10: 2 | BP10: 2 | BQ10: 2 | BR10: 2 | BS10: 2 | BT10: Não | BU10: Não | BV10: Não | BY10: Não há seção 08 no documento. Trata-se de planilha de página única, sem divisão em seções numeradas; a estrutura se limita ao quadro de itens (Grupo 1, itens 1 a 3), ao total e às notas 'Preço 01' e 'Preço 02'. | CA10: 2 | CB10: 2 | CC10: 2 | CD10: 2 | CE10: 2 | CF10: 2 | CG10: 2 | CH10: Não | CI10: Não | CJ10: Não | DA10: Não há seção 08 identificada no documento. | DC10: 2 | DD10: 2 | DE10: 2 | DF10: 2 | DG10: 2 | DH10: 2 | DI10: 2 | DJ10: Não | DK10: Não | DL10: Não | DO10: Não há seção 08 especificada no documento. | DQ10: 2 | DR10: 2 | DS10: 2 | DT10: 2 | DU10: 2 | DV10: 2 | DW10: 2 | DX10: Não | DY10: Não | DZ10: Não
A11: 11 | B11: P08 | C11: {=IFERROR(INDEX(DOCUMENTOS!$E:$E,MATCH($A11,DOCUMENTOS!$A:$A,0)),"")} | D11: {=IFERROR(INDEX('BANCO DE PERGUNTAS'!$D:$D,MATCH($B11,'BANCO DE PERGUNTAS'!$A:$A,0)),"")} -> Em qual seção do documento está localizada a informação solicitada? | E11: {=IFERROR(INDEX('BANCO DE PERGUNTAS'!$B:$B,MATCH($B11,'BANCO DE PERGUNTAS'!$A:$A,0)),"")} -> Localização | F11: {=IFERROR(INDEX('BANCO DE PERGUNTAS'!$H:$H,MATCH($B11,'BANCO DE PERGUNTAS'!$A:$A,0)),"")} -> 2 | U11: A pergunta não especifica qual informação deve ser localizada. O documento não possui seções numeradas: identificação e processo no cabeçalho; itens, preços e total na tabela central; fontes nas notas “Preço 01” e “Preço 02”; data e assinatura na parte inferior, tudo na página 1. | W11: 2 | X11: 2 | Y11: 2 | Z11: 2 | AA11: 2 | AB11: 2 | AC11: 2 | AD11: Não | AE11: Não | AF11: Não | AI11: A planilha não tem seções numeradas. Os preços e quantitativos estão na tabela central; a origem dos preços está nas notas “Preço 01” e “Preço 02” abaixo da tabela. | AK11: 2 | AL11: 2 | AM11: 2 | AN11: 2 | AO11: 2 | AP11: 2 | AQ11: 2 | AR11: Não | AS11: Não | AT11: Não | BK11: Não aplicável: o documento não possui seções numeradas. As informações estão organizadas em uma única tabela comparativa de preços e duas notas explicativas (Preço 01 e Preço 02). | BM11: 2 | BN11: 2 | BO11: 2 | BP11: 2 | BQ11: 2 | BR11: 2 | BS11: 2 | BT11: Não | BU11: Não | BV11: Não | BY11: Não aplicável: o documento não possui seções numeradas. As informações estão distribuídas entre o cabeçalho institucional, o quadro de itens, a linha de total por extenso e as notas explicativas 'Preço 01' e 'Preço 02'. | CA11: 2 | CB11: 2 | CC11: 2 | CD11: 2 | CE11: 2 | CF11: 2 | CG11: 2 | CH11: Não | CI11: Não | CJ11: Não | DA11: Não aplicável, pois não foi encontrada seção 08. | DC11: 2 | DD11: 2 | DE11: 2 | DF11: 2 | DG11: 2 | DH11: 2 | DI11: 2 | DJ11: Não | DK11: Não | DL11: Não | DO11: Não aplicável. | DQ11: 2 | DR11: 2 | DS11: 2 | DT11: 2 | DU11: 2 | DV11: 2 | DW11: 2 | DX11: Não | DY11: Não | DZ11: Não
A12: 11 | B12: P09 | C12: {=IFERROR(INDEX(DOCUMENTOS!$E:$E,MATCH($A12,DOCUMENTOS!$A:$A,0)),"")} | D12: {=IFERROR(INDEX('BANCO DE PERGUNTAS'!$D:$D,MATCH($B12,'BANCO DE PERGUNTAS'!$A:$A,0)),"")} -> Qual é o valor indicado para o Valor Total Anual do Objeto licitado? | E12: {=IFERROR(INDEX('BANCO DE PERGUNTAS'!$B:$B,MATCH($B12,'BANCO DE PERGUNTAS'!$A:$A,0)),"")} -> Localização | F12: {=IFERROR(INDEX('BANCO DE PERGUNTAS'!$H:$H,MATCH($B12,'BANCO DE PERGUNTAS'!$A:$A,0)),"")} -> 1 | U12: Total geral indicado: R$ 2.350.378,54. A denominação “Valor Total Anual do Objeto licitado” não consta no documento. Materiais e equipamentos têm quantidade de 12 meses; a periodicidade da quantidade de 434.000 m² do serviço não está explicitada. | W12: 2 | X12: 2 | Y12: 2 | Z12: 2 | AA12: 2 | AB12: 2 | AC12: 2 | AD12: Não | AE12: Não | AF12: Não | AI12: R$ 2.350.378,54 para os 12 meses indicados na planilha. | AK12: 2 | AL12: 2 | AM12: 2 | AN12: 2 | AO12: 2 | AP12: 2 | AQ12: 2 | AR12: Não | AS12: Não | AT12: Não | BK12: R$ 2.350.378,54 (dois milhões, trezentos e cinquenta mil, trezentos e setenta e oito reais e cinquenta e quatro centavos). | BM12: 2 | BN12: 2 | BO12: 2 | BP12: 2 | BQ12: 2 | BR12: 2 | BS12: 2 | BT12: Não | BU12: Não | BV12: Não | BY12: R$ 2.350.378,54 (dois milhões, trezentos e cinquenta mil, trezentos e setenta e oito reais e cinquenta e quatro centavos). Observação: o documento não emprega a expressão 'anual'; a natureza anual é inferida dos itens 2 e 3, cotados para 12 meses. | CA12: 2 | CB12: 2 | CC12: 2 | CD12: 2 | CE12: 2 | CF12: 2 | CG12: 2 | CH12: Não | CI12: Não | CJ12: Não | DA12: R$ 2.350.378,54. | DC12: 2 | DD12: 2 | DE12: 2 | DF12: 2 | DG12: 2 | DH12: 2 | DI12: 2 | DJ12: Não | DK12: Não | DL12: Não | DO12: R$ 2.350.378,54 (Dois milhões, trezentos e cinquenta mil, trezentos e setenta e oito reais e cinquenta e quatro centavos). | DQ12: 2 | DR12: 2 | DS12: 2 | DT12: 2 | DU12: 2 | DV12: 2 | DW12: 2 | DX12: Não | DY12: Não | DZ12: Não
A13: 11 | B13: P10 | C13: {=IFERROR(INDEX(DOCUMENTOS!$E:$E,MATCH($A13,DOCUMENTOS!$A:$A,0)),"")} | D13: {=IFERROR(INDEX('BANCO DE PERGUNTAS'!$D:$D,MATCH($B13,'BANCO DE PERGUNTAS'!$A:$A,0)),"")} -> Qual é a data indicada para de assinatura de todos os membros da comissão da contratação? | E13: {=IFERROR(INDEX('BANCO DE PERGUNTAS'!$B:$B,MATCH($B13,'BANCO DE PERGUNTAS'!$A:$A,0)),"")} -> Localização | F13: {=IFERROR(INDEX('BANCO DE PERGUNTAS'!$H:$H,MATCH($B13,'BANCO DE PERGUNTAS'!$A:$A,0)),"")} -> 1 | U13: não consta no documento. Há uma representação de assinatura digital de Marcos Paulo Pereira Fagundes em 24/08/2026, às 10:02:42 (-0300), mas não há identificação da comissão nem das assinaturas de todos os seus membros. | W13: 2 | X13: 2 | Y13: 2 | Z13: 2 | AA13: 2 | AB13: 2 | AC13: 2 | AD13: Não | AE13: Não | AF13: Não | AI13: Não consta no documento. Há a data “Jataí, 24 de agosto de 2026”, mas não há data de assinatura de comissão nem identificação de seus membros. | AK13: 2 | AL13: 2 | AM13: 2 | AN13: 2 | AO13: 2 | AP13: 2 | AQ13: 2 | AR13: Não | AS13: Não | AT13: Não | BK13: Não consta no documento. Há apenas uma assinatura digital individual (Marcos Paulo Pereira Fagundes, gov.br) datada de 24/08/2026; não há menção a comissão de contratação nem a assinaturas de outros membros. | BM13: 2 | BN13: 2 | BO13: 2 | BP13: 2 | BQ13: 2 | BR13: 2 | BS13: 2 | BT13: Não | BU13: Não | BV13: Não | BY13: Não consta. O documento traz uma única assinatura digital, de Marcos Paulo Pereira Fagundes, em 24/08/2026; não há identificação nem assinatura de membros de comissão ou de equipe de planejamento da contratação. | CA13: 2 | CB13: 2 | CC13: 2 | CD13: 2 | CE13: 2 | CF13: 2 | CG13: 2 | CH13: Não | CI13: Não | CJ13: Não | DA13: Não há menção a todos os membros. Consta apenas a assinatura de Marcos Paulo Pereira Fagundes em 24/08/2026 às 10:02:42. | DC13: 2 | DD13: 2 | DE13: 2 | DF13: 2 | DG13: 2 | DH13: 2 | DI13: 2 | DJ13: Não | DK13: Não | DL13: Não | DO13: Assinado digitalmente por Marcos Paulo Pereira Fagundes em 24/08/2026 10:02:42-0300 (membro/responsável signatário, sem comissão de contratação listada). | DQ13: 2 | DR13: 2 | DS13: 2 | DT13: 2 | DU13: 2 | DV13: 2 | DW13: 2 | DX13: Não | DY13: Não | DZ13: Não
A14: 11 | B14: P11 | C14: {=IFERROR(INDEX(DOCUMENTOS!$E:$E,MATCH($A14,DOCUMENTOS!$A:$A,0)),"")} | D14: {=IFERROR(INDEX('BANCO DE PERGUNTAS'!$D:$D,MATCH($B14,'BANCO DE PERGUNTAS'!$A:$A,0)),"")} -> Extraia os principais dados do documento em formato estruturado. | E14: {=IFERROR(INDEX('BANCO DE PERGUNTAS'!$B:$B,MATCH($B14,'BANCO DE PERGUNTAS'!$A:$A,0)),"")} -> Extração | F14: {=IFERROR(INDEX('BANCO DE PERGUNTAS'!$H:$H,MATCH($B14,'BANCO DE PERGUNTAS'!$A:$A,0)),"")} -> 2 | U14: Documento: Mapa Comparativo de Preços; órgão: UFJ; unidade: PROAD; processo: 23854.007448/2024-94; data: 24/08/2026; grupo: 1; CATSER dos três itens: 25194; item 1: limpeza e conservação diurna, 44 horas (A), 434.000 m², média R$ 4,84, total R$ 2.100.603,40; item 2: Material Sob Demanda + BDI, 12 meses, média R$ 17.763,49, total R$ 213.161,82; item 3: Equipamentos BDI, 12 meses, média R$ 3.051,11, total R$ 36.613,32; total geral: R$ 2.350.378,54; fontes: contrato nº 113/2024 atualizado e Banco de Preços; signatário visível: Marcos Paulo Pereira Fagundes. | W14: 2 | X14: 2 | Y14: 2 | Z14: 2 | AA14: 2 | AB14: 2 | AC14: 2 | AD14: Não | AE14: Não | AF14: Não | AI14: Processo: 23854.007448/2024-94. Unidade: UFJ/PROAD. Objeto: serviço de limpeza e conservação. Grupo: 1. Item 1: 434.000 m², serviço diurno de 44 horas, média R$ 4,84, total R$ 2.100.603,40. Item 2: 12 meses, material sob demanda + BDI, média R$ 17.763,49, total R$ 213.161,82. Item 3: 12 meses, equipamentos + BDI, média R$ 3.051,11, total R$ 36.613,32. Total: R$ 2.350.378,54. Fontes: contrato UFJ nº 113/2024 atualizado e pesquisa no Banco de Preços. Data: 24/08/2026. | AK14: 2 | AL14: 2 | AM14: 2 | AN14: 2 | AO14: 2 | AP14: 2 | AQ14: 2 | AR14: Não | AS14: Não | AT14: Não | BK14: Processo SEI: 23854.007448/2024-94 | Contrato: 113/2024 (UFJ) | Apostilamento: nº 01/2026 (0616763) | Convenção Coletiva: 2026/2027 (0602942) | Órgão: PROAD/UFJ | Data: 24/08/2026 | Item 1: limpeza/conservação, 434.000 m², média R$4,84, total R$2.100.603,40 | Item 2: material sob demanda+BDI, 12 meses, média R$17.763,49, total R$213.161,82 | Item 3: equipamentos BDI, 12 meses, média R$3.051,11, total R$36.613,32 | Valor total: R$2.350.378,54 | Fonte pesquisa: Banco de Preços. | BM14: 2 | BN14: 2 | BO14: 2 | BP14: 2 | BQ14: 2 | BR14: 2 | BS14: 2 | BT14: Não | BU14: Não | BV14: Não | BY14: Órgão: UFJ - PROAD. Documento: Planilha - Mapa Comparativo de Preços. Processo: SEI 23854.007448/2024-94. Data: 24/08/2026. Grupo 1 - Item 1: CATSER 25194, unidade m², qtd. 434.000, 'Prestação de Serviço de limpeza e conservação - Diurna - 44 horas (A)', Preço 01 R$ 4,71, Preço 02 R$ 4,97, média R$ 4,84, total R$ 2.100.603,40. Item 2: CATSER 25194, unidade Meses, qtd. 12, 'Material Sob Demanda + BDI', R$ 15.295,00 / R$ 20.231,97, média R$ 17.763,49, total R$ 213.161,82. Item 3: CATSER 25194, unidade Meses, qtd. 12, 'Equipamentos BDI', R$ 2.638,75 / R$ 3.463,47, média R$ 3.051,11, total R$ 36.613,32. Total geral: R$ 2.350.378,54. Preço 01 = contrato 113/2024 atualizado pelo Apostilamento 01/2026 (CCT 2026/2027). Preço 02 = média do Banco de Preços. | CA14: 2 | CB14: 2 | CC14: 2 | CD14: 2 | CE14: 2 | CF14: 2 | CG14: 2 | CH14: Não | CI14: Não | CJ14: Não | DA14: Processo: 23854.007448/2024-94 | Objeto: Serviços de limpeza | Valor: R$ 2.350.378,54 | Data: 24/08/2026 | Assinante: Marcos Paulo Pereira Fagundes. | DC14: 2 | DD14: 2 | DE14: 2 | DF14: 2 | DG14: 2 | DH14: 2 | DI14: 2 | DJ14: Não | DK14: Não | DL14: Não | DO14: Tabela com 3 itens: 1) Serviço de limpeza diurna 44h; 2) Material sob demanda; 3) Equipamentos, contendo quantidades, preços unitários (Contrato e Banco de Preços) e totais. | DQ14: 2 | DR14: 2 | DS14: 2 | DT14: 2 | DU14: 2 | DV14: 2 | DW14: 2 | DX14: Não | DY14: Não | DZ14: Não
A15: 11 | B15: P12 | C15: {=IFERROR(INDEX(DOCUMENTOS!$E:$E,MATCH($A15,DOCUMENTOS!$A:$A,0)),"")} | D15: {=IFERROR(INDEX('BANCO DE PERGUNTAS'!$D:$D,MATCH($B15,'BANCO DE PERGUNTAS'!$A:$A,0)),"")} -> Liste os valores financeiros presentes no documento. | E15: {=IFERROR(INDEX('BANCO DE PERGUNTAS'!$B:$B,MATCH($B15,'BANCO DE PERGUNTAS'!$A:$A,0)),"")} -> Extração | F15: {=IFERROR(INDEX('BANCO DE PERGUNTAS'!$H:$H,MATCH($B15,'BANCO DE PERGUNTAS'!$A:$A,0)),"")} -> 2 | U15: Item 1: Preço 01 R$ 4,71; Preço 02 R$ 4,97; média R$ 4,84; total R$ 2.100.603,40. Item 2: Preço 01 R$ 15.295,00; Preço 02 R$ 20.231,97; média R$ 17.763,49; total R$ 213.161,82. Item 3: Preço 01 R$ 2.638,75; Preço 02 R$ 3.463,47; média R$ 3.051,11; total R$ 36.613,32. Total geral: R$ 2.350.378,54, também escrito por extenso. | W15: 2 | X15: 2 | Y15: 2 | Z15: 2 | AA15: 2 | AB15: 2 | AC15: 2 | AD15: Não | AE15: Não | AF15: Não | AI15: Item 1: R$ 4,71; R$ 4,97; média R$ 4,84; total R$ 2.100.603,40. Item 2: R$ 15.295,00; R$ 20.231,97; média R$ 17.763,49; total R$ 213.161,82. Item 3: R$ 2.638,75; R$ 3.463,47; média R$ 3.051,11; total R$ 36.613,32. Total geral: R$ 2.350.378,54. | AK15: 2 | AL15: 2 | AM15: 2 | AN15: 2 | AO15: 2 | AP15: 2 | AQ15: 2 | AR15: Não | AS15: Não | AT15: Não | BK15: Item 1: R$4,71 (Preço01) / R$4,97 (Preço02) / R$4,84 (média) / R$2.100.603,40 (total). Item 2: R$15.295,00 / R$20.231,97 / R$17.763,49 / R$213.161,82. Item 3: R$2.638,75 / R$3.463,47 / R$3.051,11 / R$36.613,32. Total geral: R$2.350.378,54. | BM15: 2 | BN15: 2 | BO15: 2 | BP15: 2 | BQ15: 2 | BR15: 2 | BS15: 2 | BT15: Não | BU15: Não | BV15: Não | BY15: Item 1: R$ 4,71; R$ 4,97; média R$ 4,84; total R$ 2.100.603,40. Item 2: R$ 15.295,00; R$ 20.231,97; média R$ 17.763,49; total R$ 213.161,82. Item 3: R$ 2.638,75; R$ 3.463,47; média R$ 3.051,11; total R$ 36.613,32. Total geral: R$ 2.350.378,54. | CA15: 2 | CB15: 2 | CC15: 2 | CD15: 2 | CE15: 2 | CF15: 2 | CG15: 2 | CH15: Não | CI15: Não | CJ15: Não | DA15: Preços unitários: R$ 4,71; R$ 4,97; R$ 4,84; R$ 15.295,00; R$ 20.231,97; R$ 17.763,42; R$ 2.638,75; R$ 3.463,47; R$ 3.051,11. Subtotais: R$ 2.100.603,40; R$ 213.161,82; R$ 36.613,32. Total Geral: R$ 2.350.378,54. | DC15: 2 | DD15: 2 | DE15: 2 | DF15: 2 | DG15: 2 | DH15: 2 | DI15: 2 | DJ15: Não | DK15: Não | DL15: Não | DO15: R$ 4,71; R$ 4,97; R$ 4,84; R$ 2.100.603,40; R$ 15.295,00; R$ 20.231,97; R$ 17.763,42; R$ 213.161,82; R$ 2.638,75; R$ 3.463,47; R$ 3.051,11; R$ 36.613,32; R$ 2.350.378,54. | DQ15: 2 | DR15: 2 | DS15: 2 | DT15: 2 | DU15: 2 | DV15: 2 | DW15: 2 | DX15: Não | DY15: Não | DZ15: Não
A16: 11 | B16: P13 | C16: {=IFERROR(INDEX(DOCUMENTOS!$E:$E,MATCH($A16,DOCUMENTOS!$A:$A,0)),"")} | D16: {=IFERROR(INDEX('BANCO DE PERGUNTAS'!$D:$D,MATCH($B16,'BANCO DE PERGUNTAS'!$A:$A,0)),"")} -> Liste as obrigações ou responsabilidades estabelecidas. | E16: {=IFERROR(INDEX('BANCO DE PERGUNTAS'!$B:$B,MATCH($B16,'BANCO DE PERGUNTAS'!$A:$A,0)),"")} -> Extração | F16: {=IFERROR(INDEX('BANCO DE PERGUNTAS'!$H:$H,MATCH($B16,'BANCO DE PERGUNTAS'!$A:$A,0)),"")} -> 2 | U16: Obrigações ou responsabilidades expressamente atribuídas às partes: não consta no documento. O mapa apenas descreve os componentes de custo: limpeza e conservação diurna, 44 horas, materiais sob demanda com BDI e equipamentos BDI. | W16: 2 | X16: 2 | Y16: 2 | Z16: 2 | AA16: 2 | AB16: 2 | AC16: 2 | AD16: Não | AE16: Não | AF16: Não | AI16: Não há obrigações contratuais estabelecidas. A planilha registra critérios e fontes de pesquisa de preços, sem impor responsabilidades ou prazos a partes. | AK16: 2 | AL16: 2 | AM16: 2 | AN16: 2 | AO16: 2 | AP16: 2 | AQ16: 2 | AR16: Não | AS16: Não | AT16: Não | BK16: O documento não estabelece obrigações ou responsabilidades contratuais — é uma planilha comparativa de preços, não um contrato ou termo de referência. Nenhuma obrigação é fixada no texto. | BM16: 2 | BN16: 2 | BO16: 2 | BP16: 2 | BQ16: 2 | BR16: 2 | BS16: 2 | BT16: Não | BU16: Não | BV16: Não | BY16: O documento não estabelece obrigações ou responsabilidades. É peça meramente instrutória/estimativa da fase preparatória; obrigações contratuais devem ser buscadas no Termo de Referência, no edital e no contrato correspondentes. | CA16: 2 | CB16: 2 | CC16: 2 | CD16: 2 | CE16: 2 | CF16: 2 | CG16: 2 | CH16: Não | CI16: Não | CJ16: Não | DA16: Prestação de Serviço de limpeza e conservação Diurna 44 horas, além de Material Sob Demanda e Equipamentos (com BDI). | DC16: 1 | DD16: 1 | DE16: 1 | DF16: 2 | DG16: 2 | DH16: 1 | DI16: 2 | DJ16: Não | DK16: Sim | DL16: Sim | DM16: Erro de interpretação | DO16: Prestação de serviço contínuo de limpeza e conservação diurna, fornecimento de materiais sob demanda e disponibilização de equipamentos. | DQ16: 2 | DR16: 2 | DS16: 2 | DT16: 2 | DU16: 2 | DV16: 2 | DW16: 2 | DX16: Não | DY16: Não | DZ16: Não | EA16: Erro de interpretação
A17: 11 | B17: P14 | C17: {=IFERROR(INDEX(DOCUMENTOS!$E:$E,MATCH($A17,DOCUMENTOS!$A:$A,0)),"")} | D17: {=IFERROR(INDEX('BANCO DE PERGUNTAS'!$D:$D,MATCH($B17,'BANCO DE PERGUNTAS'!$A:$A,0)),"")} -> Explique o significado da cláusula/seção 4.1.4.. | E17: {=IFERROR(INDEX('BANCO DE PERGUNTAS'!$B:$B,MATCH($B17,'BANCO DE PERGUNTAS'!$A:$A,0)),"")} -> Interpretação | F17: {=IFERROR(INDEX('BANCO DE PERGUNTAS'!$H:$H,MATCH($B17,'BANCO DE PERGUNTAS'!$A:$A,0)),"")} -> 3 | U17: não consta no documento. Não há cláusula ou seção 4.1.4. | W17: 2 | X17: 2 | Y17: 2 | Z17: 2 | AA17: 2 | AB17: 2 | AC17: 2 | AD17: Não | AE17: Não | AF17: Não | AI17: Não consta no documento. Não há cláusula ou seção 4.1.4. | AK17: 2 | AL17: 2 | AM17: 2 | AN17: 2 | AO17: 2 | AP17: 2 | AQ17: 2 | AR17: Não | AS17: Não | AT17: Não | BK17: Não consta cláusula ou seção "4.1.4" neste documento; ele não possui numeração de cláusulas. | BM17: 2 | BN17: 2 | BO17: 2 | BP17: 2 | BQ17: 2 | BR17: 2 | BS17: 2 | BT17: Não | BU17: Não | BV17: Não | BY17: Não existe cláusula ou seção 4.1.4 neste documento. A planilha não é estruturada em cláusulas numeradas; a referência provavelmente pertence a outra peça do processo (Termo de Referência, edital ou contrato). | CA17: 2 | CB17: 2 | CC17: 2 | CD17: 2 | CE17: 2 | CF17: 2 | CG17: 2 | CH17: Não | CI17: Não | CJ17: Não | DA17: Não há cláusula ou seção 4.1.4 no documento. | DC17: 2 | DD17: 2 | DE17: 2 | DF17: 2 | DG17: 2 | DH17: 2 | DI17: 2 | DJ17: Não | DK17: Não | DL17: Não | DO17: Não consta cláusula ou seção 4.1.4 no documento. | DQ17: 2 | DR17: 2 | DS17: 2 | DT17: 2 | DU17: 2 | DV17: 2 | DW17: 2 | DX17: Não | DY17: Não | DZ17: Não
A18: 11 | B18: P15 | C18: {=IFERROR(INDEX(DOCUMENTOS!$E:$E,MATCH($A18,DOCUMENTOS!$A:$A,0)),"")} | D18: {=IFERROR(INDEX('BANCO DE PERGUNTAS'!$D:$D,MATCH($B18,'BANCO DE PERGUNTAS'!$A:$A,0)),"")} -> Qual é a finalidade administrativa deste documento? | E18: {=IFERROR(INDEX('BANCO DE PERGUNTAS'!$B:$B,MATCH($B18,'BANCO DE PERGUNTAS'!$A:$A,0)),"")} -> Interpretação | F18: {=IFERROR(INDEX('BANCO DE PERGUNTAS'!$H:$H,MATCH($B18,'BANCO DE PERGUNTAS'!$A:$A,0)),"")} -> 3 | U18: Subsidiar a estimativa de custos da contratação no processo 23854.007448/2024-94, mediante comparação entre valores atualizados do contrato nº 113/2024 e valores pesquisados no Banco de Preços; finalidade inferida do título e da tabela. | W18: 2 | X18: 2 | Y18: 2 | Z18: 2 | AA18: 2 | AB18: 2 | AC18: 2 | AD18: Não | AE18: Não | AF18: Não | AI18: Apoiar o planejamento da contratação, comparando referências de preços e apresentando uma estimativa para o serviço de limpeza e conservação. | AK18: 2 | AL18: 2 | AM18: 2 | AN18: 2 | AO18: 2 | AP18: 2 | AQ18: 2 | AR18: Não | AS18: Não | AT18: Não | BK18: Comparar o valor atualizado do contrato vigente (Preço 01) com a média de preços de mercado obtida no Banco de Preços (Preço 02), para subsidiar decisões administrativas relacionadas ao reajuste/repactuação do Processo SEI 23854.007448/2024-94. | BM18: 2 | BN18: 2 | BO18: 2 | BP18: 2 | BQ18: 2 | BR18: 2 | BS18: 2 | BT18: Não | BU18: Não | BV18: Não | BY18: Documentar a pesquisa de preços e fixar a estimativa do valor da contratação, instruindo a fase preparatória do procedimento (art. 23 da Lei nº 14.133/2021 e IN SEGES/ME nº 65/2021), de modo a subsidiar a autorização da despesa, a reserva orçamentária e o julgamento de propostas. | CA18: 2 | CB18: 2 | CC18: 2 | CD18: 2 | CE18: 2 | CF18: 2 | CG18: 2 | CH18: Não | CI18: Não | CJ18: Não | DA18: Comparar valores e estipular um preço médio estimado entre o contrato atual vigente e pesquisas no Banco de Preços. | DC18: 2 | DD18: 2 | DE18: 2 | DF18: 2 | DG18: 2 | DH18: 2 | DI18: 2 | DJ18: Não | DK18: Não | DL18: Não | DO18: Apresentar o comparativo de preços entre o contrato atual atualizado e a média do Banco de Preços para a contratação/manutenção dos serviços. | DQ18: 2 | DR18: 2 | DS18: 2 | DT18: 2 | DU18: 2 | DV18: 2 | DW18: 2 | DX18: Não | DY18: Não | DZ18: Não
A19: 11 | B19: P16 | C19: {=IFERROR(INDEX(DOCUMENTOS!$E:$E,MATCH($A19,DOCUMENTOS!$A:$A,0)),"")} | D19: {=IFERROR(INDEX('BANCO DE PERGUNTAS'!$D:$D,MATCH($B19,'BANCO DE PERGUNTAS'!$A:$A,0)),"")} -> Qual consequência decorre da informação estabelecida em 4.11? | E19: {=IFERROR(INDEX('BANCO DE PERGUNTAS'!$B:$B,MATCH($B19,'BANCO DE PERGUNTAS'!$A:$A,0)),"")} -> Interpretação | F19: {=IFERROR(INDEX('BANCO DE PERGUNTAS'!$H:$H,MATCH($B19,'BANCO DE PERGUNTAS'!$A:$A,0)),"")} -> 3 | U19: não consta no documento. Não há seção 4.11 da qual se possa extrair uma consequência. | W19: 2 | X19: 2 | Y19: 2 | Z19: 2 | AA19: 2 | AB19: 2 | AC19: 2 | AD19: Não | AE19: Não | AF19: Não | AI19: Não consta no documento. Não há item ou seção 4.11. | AK19: 2 | AL19: 2 | AM19: 2 | AN19: 2 | AO19: 2 | AP19: 2 | AQ19: 2 | AR19: Não | AS19: Não | AT19: Não | BK19: Não consta item "4.11" no documento; não é possível identificar tal consequência. | BM19: 2 | BN19: 2 | BO19: 2 | BP19: 2 | BQ19: 2 | BR19: 2 | BS19: 2 | BT19: Não | BU19: Não | BV19: Não | BY19: Não há item 4.11 no documento, razão pela qual nenhuma consequência pode ser extraída dele. A verificação deve ser feita na peça do processo que contenha essa numeração. | CA19: 2 | CB19: 2 | CC19: 2 | CD19: 2 | CE19: 2 | CF19: 2 | CG19: 2 | CH19: Não | CI19: Não | CJ19: Não | DA19: Não há item 4.11 no documento. | DC19: 2 | DD19: 2 | DE19: 2 | DF19: 2 | DG19: 2 | DH19: 2 | DI19: 2 | DJ19: Não | DK19: Não | DL19: Não | DO19: Não consta item 4.11 no documento. | DQ19: 2 | DR19: 2 | DS19: 2 | DT19: 2 | DU19: 2 | DV19: 2 | DW19: 2 | DX19: Não | DY19: Não | DZ19: Não
A20: 11 | B20: P17 | C20: {=IFERROR(INDEX(DOCUMENTOS!$E:$E,MATCH($A20,DOCUMENTOS!$A:$A,0)),"")} | D20: {=IFERROR(INDEX('BANCO DE PERGUNTAS'!$D:$D,MATCH($B20,'BANCO DE PERGUNTAS'!$A:$A,0)),"")} -> Existem informações aparentemente inconsistentes dentro do documento? | E20: {=IFERROR(INDEX('BANCO DE PERGUNTAS'!$B:$B,MATCH($B20,'BANCO DE PERGUNTAS'!$A:$A,0)),"")} -> Identificação de Inconsistências | F20: {=IFERROR(INDEX('BANCO DE PERGUNTAS'!$H:$H,MATCH($B20,'BANCO DE PERGUNTAS'!$A:$A,0)),"")} -> 4 | U20: Sim, há diferenças aritméticas aparentes nos valores exibidos. Item 1: 434.000 × R$ 4,84 = R$ 2.100.560,00, mas o total informado é R$ 2.100.603,40, diferença de R$ 43,40. Item 2: 12 × R$ 17.763,49 = R$ 213.161,88, mas o total informado é R$ 213.161,82, diferença de R$ 0,06. Casas decimais não exibidas podem explicar as diferenças; a memória de cálculo não consta no documento. | W20: 2 | X20: 2 | Y20: 2 | Z20: 2 | AA20: 2 | AB20: 2 | AC20: 2 | AD20: Não | AE20: Não | AF20: Não | AI20: Sim. Há possíveis divergências aritméticas: R$ 4,84 × 434.000 m² = R$ 2.100.560,00, enquanto a tabela informa R$ 2.100.603,40 (diferença de R$ 43,40). Também R$ 17.763,49 × 12 = R$ 213.161,88, enquanto a tabela informa R$ 213.161,82 (diferença de R$ 0,06). A segunda diferença pode decorrer de arredondamento de valores não exibidos; ambas devem ser conferidas com os dados de cálculo originais. | AK20: 2 | AL20: 2 | AM20: 2 | AN20: 2 | AO20: 2 | AP20: 2 | AQ20: 2 | AR20: Não | AS20: Não | AT20: Não | BK20: Sim, uma pequena inconsistência de arredondamento: no Item 1, a média exibida (R$4,84) x 434.000 m² resulta em R$2.100.560,00, mas o total informado é R$2.100.603,40 (diferença de R$43,40), sugerindo que o cálculo usou um valor não arredondado (~R$4,8403) diferente do exibido. | BM20: 2 | BN20: 2 | BO20: 2 | BP20: 2 | BQ20: 2 | BR20: 2 | BS20: 2 | BT20: Não | BU20: Não | BV20: Não | BY20: Sim. (a) No item 1, 434.000 m² x R$ 4,84 = R$ 2.100.560,00, mas o total informado é R$ 2.100.603,40 - diferença de R$ 43,40, indicando que o cálculo usou valor não arredondado (R$ 4,8401), enquanto a coluna exibe R$ 4,84. (b) O processo é de 2024 e o documento é de agosto de 2026, sem esclarecimento sobre o intervalo. (c) Os três itens usam o mesmo código CATSER 25194, embora se refiram a serviço, material e equipamentos. Os itens 2 e 3 e o somatório geral estão aritmeticamente corretos. | CA20: 2 | CB20: 2 | CC20: 2 | CD20: 2 | CE20: 2 | CF20: 2 | CG20: 2 | CH20: Não | CI20: Não | CJ20: Não | DA20: Sim, o 'Termo de Apostilamento n 01/2028' faz menção ao ano de 2028, futuro em relação à data do documento (agosto de 2026). | DC20: 1 | DD20: 1 | DE20: 1 | DF20: 2 | DG20: 2 | DH20: 1 | DI20: 2 | DJ20: Sim | DK20: Sim | DL20: Sim | DM20: Erro de interpretação | DO20: Sim, há menção ao 'Termo de Apostilamento n 01/2028' em um documento datado de 2026, o que indica um provável erro material de digitação no ano. | DQ20: 1 | DR20: 1 | DS20: 1 | DT20: 2 | DU20: 2 | DV20: 1 | DW20: 2 | DX20: Sim | DY20: Sim | DZ20: Sim | EA20: Erro de interpretação
A21: 11 | B21: P18 | C21: {=IFERROR(INDEX(DOCUMENTOS!$E:$E,MATCH($A21,DOCUMENTOS!$A:$A,0)),"")} | D21: {=IFERROR(INDEX('BANCO DE PERGUNTAS'!$D:$D,MATCH($B21,'BANCO DE PERGUNTAS'!$A:$A,0)),"")} -> Existem valores, datas, números ou informações aparentemente incompatíveis? | E21: {=IFERROR(INDEX('BANCO DE PERGUNTAS'!$B:$B,MATCH($B21,'BANCO DE PERGUNTAS'!$A:$A,0)),"")} -> Identificação de Inconsistências | F21: {=IFERROR(INDEX('BANCO DE PERGUNTAS'!$H:$H,MATCH($B21,'BANCO DE PERGUNTAS'!$A:$A,0)),"")} -> 4 | U21: Os itens 1 e 2 apresentam diferenças entre quantidade × média exibida e total informado. No item 2, a média não arredondada de R$ 15.295,00 e R$ 20.231,97 é R$ 17.763,485 e, multiplicada por 12, corresponde ao total R$ 213.161,82. O item 3 confere: 12 × R$ 3.051,11 = R$ 36.613,32. A soma dos três totais informados é R$ 2.350.378,54 e coincide com o valor por extenso. Não se identificou incompatibilidade interna entre as datas apresentadas. | W21: 1 | X21: 2 | Y21: 1 | Z21: 2 | AA21: 2 | AB21: 1 | AC21: 2 | AD21: Não | AE21: Não | AF21: Sim | AG21: Confusão de valores | AI21: Há aparentes diferenças entre o preço médio vezes a quantidade e os totais dos itens 1 e 2, conforme detalhado acima. As datas visíveis (Contrato nº 113/2024, apostilamento nº 01/2026 e mapa de 24/08/2026) não são, por si só, incompatíveis. | AK21: 2 | AL21: 2 | AM21: 2 | AN21: 2 | AO21: 2 | AP21: 2 | AQ21: 2 | AR21: Não | AS21: Não | AT21: Não | BK21: A mesma discrepância do Item 1 (média x quantidade não bate exatamente com o total apresentado, diferença de R$43,40). Os demais itens e o total geral conferem matematicamente. | BM21: 2 | BN21: 2 | BO21: 2 | BP21: 2 | BQ21: 2 | BR21: 2 | BS21: 2 | BT21: Não | BU21: Não | BV21: Não | BY21: Sim. Além da diferença de R$ 43,40 no item 1, a quantidade de 434.000 m² não indica se é área mensal ou acumulada em 12 meses (434.000/12 = 36.166,67 m²/mês), o que é essencial para conferir o total. A unidade 'Meses' nos itens 2 e 3 também não deixa claro se os valores de R$ 15.295,00 e R$ 2.638,75 são mensais. | CA21: 2 | CB21: 2 | CC21: 2 | CD21: 2 | CE21: 2 | CF21: 2 | CG21: 2 | CH21: Não | CI21: Não | CJ21: Não | DA21: Sim, a data de emissão/assinatura é 2026, mas há referência a um termo de apostilamento com ano 2028. | DC21: 1 | DD21: 1 | DE21: 1 | DF21: 2 | DG21: 2 | DH21: 1 | DI21: 2 | DJ21: Sim | DK21: Sim | DL21: Sim | DM21: Erro de interpretação | DO21: Sim, o ano 2028 no termo de apostilamento em contraste com o ano de emissão 2026. | DQ21: 1 | DR21: 1 | DS21: 1 | DT21: 2 | DU21: 2 | DV21: 1 | DW21: 2 | DX21: Sim | DY21: Sim | DZ21: Sim | EA21: Erro de interpretação
A22: 11 | B22: P19 | C22: {=IFERROR(INDEX(DOCUMENTOS!$E:$E,MATCH($A22,DOCUMENTOS!$A:$A,0)),"")} | D22: {=IFERROR(INDEX('BANCO DE PERGUNTAS'!$D:$D,MATCH($B22,'BANCO DE PERGUNTAS'!$A:$A,0)),"")} -> Existem informações relevantes ausentes? | E22: {=IFERROR(INDEX('BANCO DE PERGUNTAS'!$B:$B,MATCH($B22,'BANCO DE PERGUNTAS'!$A:$A,0)),"")} -> Identificação de Omissões | F22: {=IFERROR(INDEX('BANCO DE PERGUNTAS'!$H:$H,MATCH($B22,'BANCO DE PERGUNTAS'!$A:$A,0)),"")} -> 4 | U22: Para reproduzir integralmente a estimativa, faltam a memória de cálculo com precisão completa, a composição dos 434.000 m² e sua periodicidade, o detalhamento das cotações do Banco de Preços e a composição/percentual do BDI. Detalhamento dessas informações: não consta no documento. | W22: 2 | X22: 2 | Y22: 2 | Z22: 2 | AA22: 2 | AB22: 2 | AC22: 2 | AD22: Não | AE22: Não | AF22: Não | AI22: Sim. Não aparecem os registros detalhados da pesquisa no Banco de Preços, as cotações que formaram a média, a memória de cálculo, a identificação de quem elaborou/conferiu/aprovou a planilha, nem a assinatura dos responsáveis. A planilha também não explicita se os totais foram calculados com valores unitários não arredondados. | AK22: 2 | AL22: 2 | AM22: 2 | AN22: 2 | AO22: 2 | AP22: 2 | AQ22: 2 | AR22: Não | AS22: Não | AT22: Não | BK22: Sim: vigência contratual (datas de início/fim), dados/CNPJ da empresa contratada, identificação de quem realizou a pesquisa no Banco de Preços, número do edital/licitação de origem, e assinaturas de comissão (há apenas uma assinatura digital individual). | BM22: 2 | BN22: 2 | BO22: 2 | BP22: 2 | BQ22: 2 | BR22: 2 | BS22: 2 | BT22: Não | BU22: Não | BV22: Não | BY22: Sim: data e período de coleta dos preços no Banco de Preços; identificação das contratações similares utilizadas como parâmetro; memória de cálculo do item 1; percentual e composição do BDI; número de postos, produtividade e locais de execução; justificativa da metodologia (média simples) e do uso de apenas duas fontes; cargo/função do signatário; e indicação da dotação orçamentária. | CA22: 2 | CB22: 2 | CC22: 2 | CD22: 2 | CE22: 2 | CF22: 2 | CG22: 2 | CH22: Não | CI22: Não | CJ22: Não | DA22: O documento é apenas um mapa comparativo, faltando as memórias de cálculo detalhadas do BDI e relatórios gerados pelo Banco de Preços. | DC22: 2 | DD22: 2 | DE22: 2 | DF22: 2 | DG22: 2 | DH22: 2 | DI22: 2 | DJ22: Não | DK22: Não | DL22: Não | DO22: Detalhamento completo do cálculo analítico de BDI e encargos sociais. | DQ22: 2 | DR22: 2 | DS22: 2 | DT22: 2 | DU22: 2 | DV22: 2 | DW22: 2 | DX22: Não | DY22: Não | DZ22: Não
